<?xml version='1.0'?>
<sdf version='1.6'>
    <model name="pendulum">
        <static>false</static>
        <link name='base_link'>
            <inertial>
                <mass>10</mass>
                <inertia> 
                    <ixx>1</ixx> 
                    <ixy>0.0</ixy> 
                    <ixz>0.0</ixz> 
                    <iyy>1</iyy> 
                    <iyz>0.0</iyz>
                    <izz>1</izz>
                </inertia>
            </inertial>
            <pose>0 0 .05 0 0 0</pose>
            <collision name='collision'>
                <geometry>
                    <box>
                        <size>.3 .3 .1</size>
                    </box>
                </geometry>
            </collision>
            <visual name='visual'>
                <geometry>
                    <box>
                        <size>.3 .3 .1</size>
                    </box>
                </geometry>
                <material>
                    <ambient>0.7 0.1 0.1 1</ambient>
                    <diffuse>0.1 0.1 0.2 1</diffuse>
                    <specular>0 0 0 0</specular>
                    <emissive>0 0 0 1</emissive>
                </material>
            </visual>
        </link>

        <link name='link1'>
            <inertial>
                <mass>1.0</mass>
                <inertia>
                    <ixx>0.0133</ixx> 
                    <ixy>0.0</ixy> 
                    <ixz>0.0</ixz> 
                    <iyy>0.0133</iyy> 
                    <iyz>0.0</iyz>
                    <izz>0.00001</izz>
                </inertia>
            </inertial>
            <pose>0 0 .25 0 0 0</pose>
            <collision name='collision'>
                <geometry>
                    <box>
                        <size>.05 .05 .3</size>
                    </box>
                </geometry>
            </collision>
            <visual name='visual'>
                <geometry>
                    <box>
                        <size>.05 .05 .3</size>
                    </box>
                </geometry>
            </visual>
        </link>

        <link name='camera_link'>
            <pose>0 1 0.25 0 -0 -1.5708</pose>
            <visual name='visual'>
                <geometry>
                    <box>
                        <size>0.1 0.1 0.1</size>
                    </box>
                </geometry>
            </visual>
            <sensor name='my_camera' type='camera'>
                <camera>
                    <save enabled="false">
                        <path>/home/ryo/Desktop/camera_images</path>
                    </save>
                    <horizontal_fov>1.047</horizontal_fov>
                    <image>
                        <width>960</width>
                        <height>540</height>
                    </image>
                    <clip>
                        <near>0.1</near>
                        <far>100</far>
                    </clip>
                </camera>
                <update_rate>30</update_rate>
                <plugin name="camera_controller" filename="libgazebo_ros_camera.so">
                    <alwaysOn>true</alwaysOn>
                    <updateRate>0.0</updateRate>
                    <cameraName>ur5/camera1</cameraName>
                    <imageTopicName>image_raw</imageTopicName>
                    <cameraInfoTopicName>camera_info</cameraInfoTopicName>
                    <frameName>camera_link</frameName>
                    <hackBaseline>0.07</hackBaseline>
                    <distortionK1>0.0</distortionK1>
                    <distortionK2>0.0</distortionK2>
                    <distortionK3>0.0</distortionK3>
                    <distortionT1>0.0</distortionT1>
                    <distortionT2>0.0</distortionT2>
                </plugin>
            </sensor>
        </link>

        <joint type="revolute" name="hinge1">
            <pose>0 0 -0.15 0 0 0</pose>
            <child>link1</child>
            <parent>base_link</parent>
            <axis>
                <xyz>0 1 0</xyz>
            </axis>
        </joint>
        
        <joint type="fixed" name="base_fix">
            <pose>0 0 0 0 0 0</pose>
            <child>base_link</child>
            <parent>world</parent>
        </joint>

        <joint type="fixed" name="camera_fix">
            <pose>0 0 0 0 0 0</pose>
            <child>camera_link</child>
            <parent>world</parent>
        </joint>

        <plugin name="ur5_model_plugin" filename="libur5_model_plugin.so">
            <topic_name>ur5_action</topic_name>
        </plugin>
    </model>
</sdf>