<?xml version='1.0'?>
<sdf version='1.6'>
    <model name="pendulum">
        <static>false</static>
        <link name='base'>
            <inertial>
                <mass>10</mass>
                <inertia> 
                    <ixx>1</ixx> 
                    <ixy>0.0</ixy> 
                    <ixz>0.0</ixz> 
                    <iyy>1</iyy> 
                    <iyz>0.0</iyz>
                    <izz>1</izz>
                </inertia>
            </inertial>
            <pose>0 0 .05 0 0 0</pose>
            <collision name='collision'>
                <geometry>
                    <box>
                        <size>.3 .3 .1</size>
                    </box>
                </geometry>
            </collision>
            <visual name='visual'>
                <geometry>
                    <box>
                        <size>.3 .3 .1</size>
                    </box>
                </geometry>
            </visual>
        </link>

        <link name='link1'>
            <inertial>
                <mass>1.0</mass>
                <inertia>
                    <ixx>0.0133</ixx> 
                    <ixy>0.0</ixy> 
                    <ixz>0.0</ixz> 
                    <iyy>0.0133</iyy> 
                    <iyz>0.0</iyz>
                    <izz>0.00001</izz>
                </inertia>
            </inertial>
            <pose>0 0 .25 0 0 0</pose>
            <collision name='collision'>
                <geometry>
                    <box>
                        <size>.05 .05 .3</size>
                    </box>
                </geometry>
            </collision>
            <visual name='visual'>
                <geometry>
                    <box>
                        <size>.05 .05 .3</size>
                    </box>
                </geometry>
            </visual>
        </link>

        <joint type="revolute" name="hinge1">
            <pose>0 0 -0.15 0 0 0</pose>
            <child>link1</child>
            <parent>base</parent>
            <axis>
                <xyz>0 1 0</xyz>
            </axis>
        </joint>
        
        <joint type="fixed" name="fix">
            <pose>0 0 0 0 0 0</pose>
            <child>base</child>
            <parent>world</parent>
        </joint>

        <plugin name="ur5_model_plugin" filename="libur5_model_plugin.so">
            <topic_name>ur5_action</topic_name>
        </plugin>
    </model>  
</sdf>